//
//  ExceptionTestingTests.swift
//  MetovaTestKit
//
//  Created by Nick Griffith on 5/7/16.
//  Copyright Â© 2016 Metova. All rights reserved.
//

import XCTest

@testable import MetovaTestKit

class ExceptionTestingTests: MTKBaseTestCase {

    func testAssertNoExceptionPasses() {
        
        var didReachEnd: Bool?
        
        MTKAssertNoException(message: "TEST MESSAGE") {
            didReachEnd = false

            let arr: NSArray = [0, 1, 3, 4, 5, 6, 7, 8, 9, 10]
            arr.objectAtIndex(3)
            
            didReachEnd = true
        }
        
        guard let endReached = didReachEnd else {
            XCTFail("Test block was not executed.")
            return
        }
        
        XCTAssertTrue(endReached)
    }
    
    func testAssertNoExceptionDefaultMessagePasses() {
        
        var didReachEnd: Bool?
        
        MTKAssertNoException {
            didReachEnd = false
            
            let arr: NSArray = [0, 1, 3, 4, 5, 6, 7, 8, 9, 10]
            arr.objectAtIndex(3)
            
            didReachEnd = true
        }
        
        guard let endReached = didReachEnd else {
            XCTFail("Test block was not executed.")
            return
        }
        
        XCTAssertTrue(endReached)
    }
    
    func testAssertNoExceptionFails() {
        // TODO: Find a way to verify that MTKAssertNoException fails.  I know it fails, but the only way I can get it to fail also fails *this* test itself.  How do we verify a test fails without failing the test that's testing it?
    }
    
    func testAssertNoExceptionDefaultMessageFails() {
        // TODO: Same as above method, but use default for message argument.
    }
    
    func testAssertNoExceptionReturnsNilWhenPassing() {
        
        let exception = MTKAssertNoException {
            let arr: NSArray = [0, 1, 3, 4, 5, 6, 7, 8, 9, 10]
            arr.objectAtIndex(3)
        }
        
        XCTAssertNil(exception)
    }
    
    func testAssertExceptionPasses() {
        
        var didReachEnd: Bool?
        
        MTKAssertException(message: "TEST MESSAGE") {
            didReachEnd = false
            
            let arr = NSArray()
            arr.objectAtIndex(3)
            
            didReachEnd = true
        }
        
        guard let endReached = didReachEnd else {
            XCTFail("Test block was not executed.")
            return
        }
        
        XCTAssertFalse(endReached)
    }
    
    func testAssertExceptionDefaultMessagePasses() {
        
        var didReachEnd: Bool?
        
        MTKAssertException {
            didReachEnd = false
            
            let arr = NSArray()
            arr.objectAtIndex(3)
            
            didReachEnd = true
        }
        
        guard let endReached = didReachEnd else {
            XCTFail("Test block was not executed.")
            return
        }
        
        XCTAssertFalse(endReached)
    }
    
    func testAssertExceptionFails() {
        // TODO: Find a way to verify that MTKAssertException fails.  I know it fails, but the only way I can get it to fail also fails *this* test itself.  How do we verify a test fails without failing the test that's testing it?
    }
    
    func testAssertExceptionDefaultMessageFails() {
        // TODO: Same as above method, but use default for message argument.
    }
    
    func testAssertExceptionCatchesCorrectException() {

        let throwingBlock = {
            let arr = NSArray()
            arr.objectAtIndex(3)
        }
        
        guard let exception = MTKAssertException(testBlock: throwingBlock) else {
            XCTFail("Failed to catch exception")
            return
        }
        
        XCTAssertEqual(exception.name, "NSRangeException")
        XCTAssertEqual(exception.reason, "*** -[__NSArray0 objectAtIndex:]: index 3 beyond bounds for empty NSArray")
    }
    
}
